Workbook

Sheet Read me
A1: CX AI Fit Assessment, v0 model
A3: What this is: the v0 of the fit assessment from the structure doc. A consultant runs it by hand on a live deal.
A4: Legend: blue text on yellow = input. Black = formula. Green = pulled from another sheet. Change inputs only.
A5: The client in here is an illustrative example (Example Energy Co). Overwrite every input for a real client.
A6: Order of work: Questionnaire, then Intents (top 20 with share, type, consequence), then Readiness (score 1 to 5), then check Results.
A7: Matrix: real platform rows are blank. The team scores them 0 to 3 per column and sets a year-one cost band. The three example rows are illustrative placeholders only, not real platforms. Delete them once real rows are scored.
A8: Settings holds every factor and threshold. All are illustrative until calibrated on the first five clients.
A9: Scoring: opportunity per intent = share x automatability x risk factor. Automatable share = sum of opportunity. Phase 1 = top five by opportunity with the readiness it depends on at 3 or more (informational needs Knowledge, transactional needs Integration, everything needs People).
A10: Fit score = sum(weight x score) / (3 x sum(weight)). Over-spec index = scores in columns the profile weights 0: what they would pay for and not use. Budget filter runs before ranking.
A11: Sheets with a space in the name are quoted in formulas. Do not rename sheets.

Sheet Settings
A1: Settings
A2: Factors, thresholds and dropdown lists. Blue cells can be changed. Every threshold is illustrative until calibrated on real clients.
A3: Intent type | B3: Automatability factor | D3: Yes/No | E3: Owner | F3: Builder skills | G3: Residency | H3: Self-service today | I3: AI policy | J3: Goal | K3: Customer type
A4: Informational, content exists | B4: 1 | D4: Yes | E4: Nobody yet | F4: None | G4: Any cloud | H4: None | I4: Approved | J4: Cost per contact | K4: Consumers
A5: Informational, content needs writing | B5: 0.8 | D5: No | E5: CX team | F5: Some | G5: EU | H5: Help centre | I5: Drafting | J5: CSAT | K5: Businesses
A6: Transactional, API exists | B6: 0.9 | E6: IT | F6: Yes | G6: UK only | H6: IVR | I6: None | J6: 24/7 cover | K6: Citizens
A7: Transactional, no API | B7: 0.5 | E7: Vendor | H7: Bot | J7: Agent load | K7: Employees
A8: Complex | B8: 0.2 | E8: Partner | H8: Several | J8: Consistency
A9: Regulated | B9: 0
A11: Consequence of a wrong answer | B11: Risk factor
A12: Low | B12: 1
A13: Medium | B13: 0.8
A14: High | B14: 0.5
A16: Threshold (illustrative) | B16: Value
A17: No platform below this automatable share | B17: 0.15
A18: Full platform above this automatable share | B18: 0.35
A19: Voice heavy above this voice share of volume | B19: 0.4
A20: Transactional heavy above this transactional share of volume | B20: 0.25
A21: Voice weight 3 above this voice share | B21: 0.4
A22: Voice weight 1 above this voice share | B22: 0.1
A23: Integration weight 3 above this transactional share | B23: 0.25
A24: Knowledge weight 3 above this informational share | B24: 0.4
A25: Languages weight 2 when more than this many | B25: 2
A26: Top-quartile count of 20 intents | B26: 5
A27: Readiness minimum for Phase 1 | B27: 3
A29: Budget band (year one, licences and build) | B29: Index
A30: Under £50k | B30: 1
A31: £50k to £150k | B31: 2
A32: £150k to £400k | B32: 3
A33: Over £400k | B33: 4

Sheet Questionnaire
A1: Questionnaire
A2: Blue cells on yellow are inputs. The values in them are an illustrative example client: overwrite them. Intents B1 to B4 live on the Intents sheet.
B3: Client | C3: Example Energy Co (illustrative)
B4: Assessment date | C4: 2026-10-05
A6: # | B6: Question | C6: Answer | D6: Format | E6: Feeds
A7: A. Contact profile
A8: A1a | B8: Voice contacts per month | C8: 18000 | D8: Number | E8: Profile: volume, voice share
A9: A1b | B9: Chat contacts per month | C9: 6000 | D9: Number | E9: Profile: volume, messaging share
A10: A1c | B10: Email contacts per month | C10: 9000 | D10: Number | E10: Profile: volume
A11: A1d | B11: Social contacts per month | C11: 500 | D11: Number | E11: Profile: volume, messaging share
A12: A1e | B12: In-app contacts per month | C12: 1500 | D12: Number | E12: Profile: volume, messaging share
A13: A1f | B13: Other contacts per month | C13: 0 | D13: Number | E13: Profile: volume
A14: A2 | B14: Share of contacts arriving out of hours | C14: 0.22 | D14: Percent | E14: Profile: 24/7 case
A15: A3 | B15: Peak month divided by quietest month | C15: 1.6 | D15: Number | E15: Profile: elasticity
A16: A4 | B16: Number of languages customers contact you in | C16: 2 | D16: Number | E16: Profile: languages
A17: A4b | B17: Which languages, with rough share | C17: English 94%, Welsh 6% | D17: Text | E17: Report
A18: A5 | B18: Who the customers are | C18: Consumers | D18: Pick: Customer type | E18: Profile: tone, auth model
A19: A6 | B19: Must customers be identified before you can help? | C19: Yes | D19: Pick: Yes/No | E19: Profile: auth needed
A20: A6b | B20: How are they identified today? | C20: Account number plus postcode | D20: Text | E20: Report
A22: B. Intents (B1 to B4 are on the Intents sheet)
A23: B5a | B23: Repeat contact rate | C23: 0.18 | D23: Percent | E23: Opportunity: value. Readiness: data
A24: B5b | B24: First contact resolution | C24: 0.72 | D24: Percent | E24: Opportunity: value. Readiness: data
A25: B6a | B25: Self-service today | C25: Help centre | D25: Pick: Self-service today | E25: Profile: baseline
A26: B6b | B26: Containment rate today, if known | C26: 0.08 | D26: Percent | E26: Profile: baseline
A27: B7 | B27: Blended cost per contact (£) | C27: 4.5 | D27: Number | E27: Opportunity: value
A29: C. Systems
A30: C1 | B30: Ticketing or CRM platform and version | C30: Zendesk Suite | D30: Text | E30: Profile: handoff target
A31: C2 | B31: Telephony or contact centre platform | C31: NICE CXone | D31: Text | E31: Profile: voice handoff
A32: C3 | B32: Back-office systems behind the top transactional intents, API available, owner | C32: Billing (API yes, IT), Scheduling (no API, Ops) | D32: Text | E32: Readiness: integration
A33: C4 | B33: Could a bot reuse the current verification method? | C33: Yes | D33: Pick: Yes/No | E33: Readiness: integration. Profile: auth
A34: C5 | B34: Hosting or data residency constraint | C34: UK only | D34: Pick: Residency | E34: Profile: constraints
A36: D. Knowledge
A37: D1a | B37: Public help centre? | C37: Yes | D37: Pick: Yes/No | E37: Readiness: knowledge
A38: D1b | B38: Help centre platform and article count | C38: Zendesk Guide, 140 articles | D38: Text | E38: Readiness: knowledge
A39: D2a | B39: Last reviewed end to end | C39: 2025-03 | D39: Text | E39: Readiness: knowledge
A40: D2b | B40: Who owns it (role) | C40: Digital content lead, part time | D40: Text | E40: Readiness: knowledge
A41: D3 | B41: Do agents use it, or their own notes and macros? | C41: Own notes | D41: Text | E41: Readiness: knowledge
A42: D4 | B42: Internal knowledge base agents trust? | C42: No | D42: Pick: Yes/No | E42: Readiness: knowledge
A43: D5 | B43: Tone of voice or brand guidelines for written contact? | C43: Yes | D43: Pick: Yes/No | E43: Profile: content effort
A45: E. People
...

Sheet Readiness
A1: Readiness
A2: Score each dimension 1 to 5 against the descriptions. People is a gate: a 1 means no platform yet, whatever the opportunity says.
A4: Dimension | B4: Score (1 to 5) | C4: What a 1 looks like | D4: What a 3 looks like | E4: What a 5 looks like
A5: Data | B5: 3 | C5: No reason codes, no exports | D5: Reason codes exist but messy | E5: Clean taxonomy, exports on tap
A6: Knowledge | B6: 2 | C6: No help centre, or badly out of date | D6: Exists, partly maintained | E6: Current, owned, agents use it
A7: Integration | B7: 4 | C7: No APIs, systems locked down | D7: Some APIs, IT will help | E7: API-first, auth solved
A8: People | B8: 3 | C8: Nobody to own it | D8: Owner named, no skills yet | E8: Owner plus someone who can build and maintain
A9: Governance | B9: 3 | C9: No policy, blockers unknown | D9: Constraints known, no sign-off process | E9: AI policy, sign-off and review in place
A11: People gate | B11: =IF(B8<=1,"GATE: no platform yet, sort the owner first","Open") -> Open
A12: Average readiness | B12: =AVERAGE(B5:B9) -> 3

Sheet Intents
A1: Intents (B1 to B4)
A2: Top 20 contact reasons. Blue cells are inputs; the example rows are illustrative. Shares are of all contacts and need not reach 100%.
A4: # | B4: Intent | C4: Share of volume | D4: Type | E4: Wrong-answer consequence | F4: System or API note | G4: Automatability | H4: Risk factor | I4: Opportunity | J4: Annual value (£, illustrative) | K4: Depends on | L4: Dependency score | M4: Status | N4: Informational share | O4: Transactional share | P4: Phase 1 # | Q4: Fix first #
A5: 1 | B5: Submit a meter reading | C5: 0.11 | D5: Transactional, API exists | E5: Low | F5: Billing API | G5: =IF(D5="","",IFERROR(INDEX(Settings!$B$4:$B$9,MATCH(D5,Settings!$A$4:$A$9,0)),"")) -> 0.9 | H5: =IF(E5="","",IFERROR(INDEX(Settings!$B$12:$B$14,MATCH(E5,Settings!$A$12:$A$14,0)),"")) -> 1 | I5: =IF(OR(C5="",G5="",H5=""),"",C5*G5*H5) -> 0.099 | J5: =IF(I5="","",Profile!$C$4*I5*Questionnaire!$C$27*12) -> 187110 | K5: =IF(D5="","",IF(LEFT(D5,13)="Informational","Knowledge",IF(LEFT(D5,13)="Transactional","Integration","People"))) -> Integration | L5: =IF(K5="","",MIN(INDEX(Readiness!$B$5:$B$9,MATCH(K5,Readiness!$A$5:$A$9,0)),Readiness!$B$8)) -> 3 | M5: =IF(I5="","",IF(G5=0,"Regulated, stays human",IF(AND(I5>0,RANK(I5,$I$5:$I$24,0)<=Settings!$B$26),IF(L5>=Settings!$B$27,"Phase 1","Fix first"),IF(L5>=Settings!$B$27,"Later","Leave with humans")))) -> Phase 1 | N5: =IF(OR(C5="",D5=""),0,IF(LEFT(D5,13)="Informational",C5,0)) -> 0 | O5: =IF(OR(C5="",D5=""),0,IF(LEFT(D5,13)="Transactional",C5,0)) -> 0.11 | P5: =IF(M5="Phase 1",COUNTIF($M$5:M5,"Phase 1"),"") -> 1 | Q5: =IF(M5="Fix first",COUNTIF($M$5:M5,"Fix first"),"")
A6: 2 | B6: Make a payment | C6: 0.09 | D6: Transactional, API exists | E6: Medium | F6: Payment gateway, PCI | G6: =IF(D6="","",IFERROR(INDEX(Settings!$B$4:$B$9,MATCH(D6,Settings!$A$4:$A$9,0)),"")) -> 0.9 | H6: =IF(E6="","",IFERROR(INDEX(Settings!$B$12:$B$14,MATCH(E6,Settings!$A$12:$A$14,0)),"")) -> 0.8 | I6: =IF(OR(C6="",G6="",H6=""),"",C6*G6*H6) -> 0.0648 | J6: =IF(I6="","",Profile!$C$4*I6*Questionnaire!$C$27*12) -> 122472 | K6: =IF(D6="","",IF(LEFT(D6,13)="Informational","Knowledge",IF(LEFT(D6,13)="Transactional","Integration","People"))) -> Integration | L6: =IF(K6="","",MIN(INDEX(Readiness!$B$5:$B$9,MATCH(K6,Readiness!$A$5:$A$9,0)),Readiness!$B$8)) -> 3 | M6: =IF(I6="","",IF(G6=0,"Regulated, stays human",IF(AND(I6>0,RANK(I6,$I$5:$I$24,0)<=Settings!$B$26),IF(L6>=Settings!$B$27,"Phase 1","Fix first"),IF(L6>=Settings!$B$27,"Later","Leave with humans")))) -> Phase 1 | N6: =IF(OR(C6="",D6=""),0,IF(LEFT(D6,13)="Informational",C6,0)) -> 0 | O6: =IF(OR(C6="",D6=""),0,IF(LEFT(D6,13)="Transactional",C6,0)) -> 0.09 | P6: =IF(M6="Phase 1",COUNTIF($M$5:M6,"Phase 1"),"") -> 2 | Q6: =IF(M6="Fix first",COUNTIF($M$5:M6,"Fix first"),"")
A7: 3 | B7: Bill explanation (why is it higher) | C7: 0.1 | D7: Complex | E7: Medium | G7: =IF(D7="","",IFERROR(INDEX(Settings!$B$4:$B$9,MATCH(D7,Settings!$A$4:$A$9,0)),"")) -> 0.2 | H7: =IF(E7="","",IFERROR(INDEX(Settings!$B$12:$B$14,MATCH(E7,Settings!$A$12:$A$14,0)),"")) -> 0.8 | I7: =IF(OR(C7="",G7="",H7=""),"",C7*G7*H7) -> 0.016 | J7: =IF(I7="","",Profile!$C$4*I7*Questionnaire!$C$27*12) -> 30240 | K7: =IF(D7="","",IF(LEFT(D7,13)="Informational","Knowledge",IF(LEFT(D7,13)="Transactional","Integration","People"))) -> People | L7: =IF(K7="","",MIN(INDEX(Readiness!$B$5:$B$9,MATCH(K7,Readiness!$A$5:$A$9,0)),Readiness!$B$8)) -> 3 | M7: =IF(I7="","",IF(G7=0,"Regulated, stays human",IF(AND(I7>0,RANK(I7,$I$5:$I$24,0)<=Settings!$B$26),IF(L7>=Settings!$B$27,"Phase 1","Fix first"),IF(L7>=Settings!$B$27,"Later","Leave with humans")))) -> Later | N7: =IF(OR(C7="",D7=""),0,IF(LEFT(D7,13)="Informational",C7,0)) -> 0 | O7: =IF(OR(C7="",D7=""),0,IF(LEFT(D7,13)="Transactional",C7,0)) -> 0 | P7: =IF(M7="Phase 1",COUNTIF($M$5:M7,"Phase 1"),"") | Q7: =IF(M7="Fix first",COUNTIF($M$5:M7,"Fix first"),"")
A8: 4 | B8: Moving home | C8: 0.06 | D8: Transactional, no API | E8: Medium | F8: Manual in billing | G8: =IF(D8="","",IFERROR(INDEX(Settings!$B$4:$B$9,MATCH(D8,Settings!$A$4:$A$9,0)),"")) -> 0.5 | H8: =IF(E8="","",IFERROR(INDEX(Settings!$B$12:$B$14,MATCH(E8,Settings!$A$12:$A$14,0)),"")) -> 0.8 | I8: =IF(OR(C8="",G8="",H8=""),"",C8*G8*H8) -> 0.024 | J8: =IF(I8="","",Profile!$C$4*I8*Questionnaire!$C$27*12) -> 45360 | K8: =IF(D8="","",IF(LEFT(D8,13)="Informational","Knowledge",IF(LEFT(D8,13)="Transactional","Integration","People"))) -> Integration | L8: =IF(K8="","",MIN(INDEX(Readiness!$B$5:$B$9,MATCH(K8,Readiness!$A$5:$A$9,0)),Readiness!$B$8)) -> 3 | M8: =IF(I8="","",IF(G8=0,"Regulated, stays human",IF(AND(I8>0,RANK(I8,$I$5:$I$24,0)<=Settings!$B$26),IF(L8>=Settings!$B$27,"Phase 1","Fix first"),IF(L8>=Settings!$B$27,"Later","Leave with humans")))) -> Later | N8: =IF(OR(C8="",D8=""),0,IF(LEFT(D8,13)="Informational",C8,0)) -> 0 | O8: =IF(OR(C8="",D8=""),0,IF(LEFT(D8,13)="Transactional",C8,0)) -> 0.06 | P8: =IF(M8="Phase 1",COUNTIF($M$5:M8,"Phase 1"),"") | Q8: =IF(M8="Fix first",COUNTIF($M$5:M8,"Fix first"),"")
A9: 5 | B9: Update contact details | C9: 0.05 | D9: Transactional, API exists | E9: Low | F9: CRM API | G9: =IF(D9="","",IFERROR(INDEX(Settings!$B$4:$B$9,MATCH(D9,Settings!$A$4:$A$9,0)),"")) -> 0.9 | H9: =IF(E9="","",IFERROR(INDEX(Settings!$B$12:$B$14,MATCH(E9,Settings!$A$12:$A$14,0)),"")) -> 1 | I9: =IF(OR(C9="",G9="",H9=""),"",C9*G9*H9) -> 0.045 | J9: =IF(I9="","",Profile!$C$4*I9*Questionnaire!$C$27*12) -> 85050 | K9: =IF(D9="","",IF(LEFT(D9,13)="Informational","Knowledge",IF(LEFT(D9,13)="Transactional","Integration","People"))) -> Integration | L9: =IF(K9="","",MIN(INDEX(Readiness!$B$5:$B$9,MATCH(K9,Readiness!$A$5:$A$9,0)),Readiness!$B$8)) -> 3 | M9: =IF(I9="","",IF(G9=0,"Regulated, stays human",IF(AND(I9>0,RANK(I9,$I$5:$I$24,0)<=Settings!$B$26),IF(L9>=Settings!$B$27,"Phase 1","Fix first"),IF(L9>=Settings!$B$27,"Later","Leave with humans")))) -> Phase 1 | N9: =IF(OR(C9="",D9=""),0,IF(LEFT(D9,13)="Informational",C9,0)) -> 0 | O9: =IF(OR(C9="",D9=""),0,IF(LEFT(D9,13)="Transactional",C9,0)) -> 0.05 | P9: =IF(M9="Phase 1",COUNTIF($M$5:M9,"Phase 1"),"") -> 3 | Q9: =IF(M9="Fix first",COUNTIF($M$5:M9,"Fix first"),"")
A10: 6 | B10: Payment plan or arrears | C10: 0.06 | D10: Regulated | E10: High | F10: Must be human | G10: =IF(D10="","",IFERROR(INDEX(Settings!$B$4:$B$9,MATCH(D10,Settings!$A$4:$A$9,0)),"")) -> 0 | H10: =IF(E10="","",IFERROR(INDEX(Settings!$B$12:$B$14,MATCH(E10,Settings!$A$12:$A$14,0)),"")) -> 0.5 | I10: =IF(OR(C10="",G10="",H10=""),"",C10*G10*H10) -> 0 | J10: =IF(I10="","",Profile!$C$4*I10*Questionnaire!$C$27*12) -> 0 | K10: =IF(D10="","",IF(LEFT(D10,13)="Informational","Knowledge",IF(LEFT(D10,13)="Transactional","Integration","People"))) -> People | L10: =IF(K10="","",MIN(INDEX(Readiness!$B$5:$B$9,MATCH(K10,Readiness!$A$5:$A$9,0)),Readiness!$B$8)) -> 3 | M10: =IF(I10="","",IF(G10=0,"Regulated, stays human",IF(AND(I10>0,RANK(I10,$I$5:$I$24,0)<=Settings!$B$26),IF(L10>=Settings!$B$27,"Phase 1","Fix first"),IF(L10>=Settings!$B$27,"Later","Leave with humans")))) -> Regulated, stays human | N10: =IF(OR(C10="",D10=""),0,IF(LEFT(D10,13)="Informational",C10,0)) -> 0 | O10: =IF(OR(C10="",D10=""),0,IF(LEFT(D10,13)="Transactional",C10,0)) -> 0 | P10: =IF(M10="Phase 1",COUNTIF($M$5:M10,"Phase 1"),"") | Q10: =IF(M10="Fix first",COUNTIF($M$5:M10,"Fix first"),"")
A11: 7 | B11: Change direct debit date | C11: 0.04 | D11: Transactional, API exists | E11: Low | F11: Billing API | G11: =IF(D11="","",IFERROR(INDEX(Settings!$B$4:$B$9,MATCH(D11,Settings!$A$4:$A$9,0)),"")) -> 0.9 | H11: =IF(E11="","",IFERROR(INDEX(Settings!$B$12:$B$14,MATCH(E11,Settings!$A$12:$A$14,0)),"")) -> 1 | I11: =IF(OR(C11="",G11="",H11=""),"",C11*G11*H11) -> 0.036 | J11: =IF(I11="","",Profile!$C$4*I11*Questionnaire!$C$27*12) -> 68040 | K11: =IF(D11="","",IF(LEFT(D11,13)="Informational","Knowledge",IF(LEFT(D11,13)="Transactional","Integration","People"))) -> Integration | L11: =IF(K11="","",MIN(INDEX(Readiness!$B$5:$B$9,MATCH(K11,Readiness!$A$5:$A$9,0)),Readiness!$B$8)) -> 3 | M11: =IF(I11="","",IF(G11=0,"Regulated, stays human",IF(AND(I11>0,RANK(I11,$I$5:$I$24,0)<=Settings!$B$26),IF(L11>=Settings!$B$27,"Phase 1","Fix first"),IF(L11>=Settings!$B$27,"Later","Leave with humans")))) -> Later | N11: =IF(OR(C11="",D11=""),0,IF(LEFT(D11,13)="Informational",C11,0)) -> 0 | O11: =IF(OR(C11="",D11=""),0,IF(LEFT(D11,13)="Transactional",C11,0)) -> 0.04 | P11: =IF(M11="Phase 1",COUNTIF($M$5:M11,"Phase 1"),"") | Q11: =IF(M11="Fix first",COUNTIF($M$5:M11,"Fix first"),"")
A12: 8 | B12: Book smart meter appointment | C12: 0.05 | D12: Transactional, no API | E12: Medium | F12: Scheduling, no API | G12: =IF(D12="","",IFERROR(INDEX(Settings!$B$4:$B$9,MATCH(D12,Settings!$A$4:$A$9,0)),"")) -> 0.5 | H12: =IF(E12="","",IFERROR(INDEX(Settings!$B$12:$B$14,MATCH(E12,Settings!$A$12:$A$14,0)),"")) -> 0.8 | I12: =IF(OR(C12="",G12="",H12=""),"",C12*G12*H12) -> 0.02 | J12: =IF(I12="","",Profile!$C$4*I12*Questionnaire!$C$27*12) -> 37800 | K12: =IF(D12="","",IF(LEFT(D12,13)="Informational","Knowledge",IF(LEFT(D12,13)="Transactional","Integration","People"))) -> Integration | L12: =IF(K12="","",MIN(INDEX(Readiness!$B$5:$B$9,MATCH(K12,Readiness!$A$5:$A$9,0)),Readiness!$B$8)) -> 3 | M12: =IF(I12="","",IF(G12=0,"Regulated, stays human",IF(AND(I12>0,RANK(I12,$I$5:$I$24,0)<=Settings!$B$26),IF(L12>=Settings!$B$27,"Phase 1","Fix first"),IF(L12>=Settings!$B$27,"Later","Leave with humans")))) -> Later | N12: =IF(OR(C12="",D12=""),0,IF(LEFT(D12,13)="Informational",C12,0)) -> 0 | O12: =IF(OR(C12="",D12=""),0,IF(LEFT(D12,13)="Transactional",C12,0)) -> 0.05 | P12: =IF(M12="Phase 1",COUNTIF($M$5:M12,"Phase 1"),"") | Q12: =IF(M12="Fix first",COUNTIF($M$5:M12,"Fix first"),"")
A13: 9 | B13: Tariff information | C13: 0.04 | D13: Informational, content exists | E13: Low | G13: =IF(D13="","",IFERROR(INDEX(Settings!$B$4:$B$9,MATCH(D13,Settings!$A$4:$A$9,0)),"")) -> 1 | H13: =IF(E13="","",IFERROR(INDEX(Settings!$B$12:$B$14,MATCH(E13,Settings!$A$12:$A$14,0)),"")) -> 1 | I13: =IF(OR(C13="",G13="",H13=""),"",C13*G13*H13) -> 0.04 | J13: =IF(I13="","",Profile!$C$4*I13*Questionnaire!$C$27*12) -> 75600 | K13: =IF(D13="","",IF(LEFT(D13,13)="Informational","Knowledge",IF(LEFT(D13,13)="Transactional","Integration","People"))) -> Knowledge | L13: =IF(K13="","",MIN(INDEX(Readiness!$B$5:$B$9,MATCH(K13,Readiness!$A$5:$A$9,0)),Readiness!$B$8)) -> 2 | M13: =IF(I13="","",IF(G13=0,"Regulated, stays human",IF(AND(I13>0,RANK(I13,$I$5:$I$24,0)<=Settings!$B$26),IF(L13>=Settings!$B$27,"Phase 1","Fix first"),IF(L13>=Settings!$B$27,"Later","Leave with humans")))) -> Fix first | N13: =IF(OR(C13="",D13=""),0,IF(LEFT(D13,13)="Informational",C13,0)) -> 0.04 | O13: =IF(OR(C13="",D13=""),0,IF(LEFT(D13,13)="Transactional",C13,0)) -> 0 | P13: =IF(M13="Phase 1",COUNTIF($M$5:M13,"Phase 1"),"") | Q13: =IF(M13="Fix first",COUNTIF($M$5:M13,"Fix first"),"") -> 1
A14: 10 | B14: Power cut or supply issue | C14: 0.03 | D14: Regulated | E14: High | F14: Network operator | G14: =IF(D14="","",IFERROR(INDEX(Settings!$B$4:$B$9,MATCH(D14,Settings!$A$4:$A$9,0)),"")) -> 0 | H14: =IF(E14="","",IFERROR(INDEX(Settings!$B$12:$B$14,MATCH(E14,Settings!$A$12:$A$14,0)),"")) -> 0.5 | I14: =IF(OR(C14="",G14="",H14=""),"",C14*G14*H14) -> 0 | J14: =IF(I14="","",Profile!$C$4*I14*Questionnaire!$C$27*12) -> 0 | K14: =IF(D14="","",IF(LEFT(D14,13)="Informational","Knowledge",IF(LEFT(D14,13)="Transactional","Integration","People"))) -> People | L14: =IF(K14="","",MIN(INDEX(Readiness!$B$5:$B$9,MATCH(K14,Readiness!$A$5:$A$9,0)),Readiness!$B$8)) -> 3 | M14: =IF(I14="","",IF(G14=0,"Regulated, stays human",IF(AND(I14>0,RANK(I14,$I$5:$I$24,0)<=Settings!$B$26),IF(L14>=Settings!$B$27,"Phase 1","Fix first"),IF(L14>=Settings!$B$27,"Later","Leave with humans")))) -> Regulated, stays human | N14: =IF(OR(C14="",D14=""),0,IF(LEFT(D14,13)="Informational",C14,0)) -> 0 | O14: =IF(OR(C14="",D14=""),0,IF(LEFT(D14,13)="Transactional",C14,0)) -> 0 | P14: =IF(M14="Phase 1",COUNTIF($M$5:M14,"Phase 1"),"") | Q14: =IF(M14="Fix first",COUNTIF($M$5:M14,"Fix first"),"")
A15: 11 | B15: Refund request | C15: 0.03 | D15: Transactional, no API | E15: Medium | F15: Finance queue | G15: =IF(D15="","",IFERROR(INDEX(Settings!$B$4:$B$9,MATCH(D15,Settings!$A$4:$A$9,0)),"")) -> 0.5 | H15: =IF(E15="","",IFERROR(INDEX(Settings!$B$12:$B$14,MATCH(E15,Settings!$A$12:$A$14,0)),"")) -> 0.8 | I15: =IF(OR(C15="",G15="",H15=""),"",C15*G15*H15) -> 0.012 | J15: =IF(I15="","",Profile!$C$4*I15*Questionnaire!$C$27*12) -> 22680 | K15: =IF(D15="","",IF(LEFT(D15,13)="Informational","Knowledge",IF(LEFT(D15,13)="Transactional","Integration","People"))) -> Integration | L15: =IF(K15="","",MIN(INDEX(Readiness!$B$5:$B$9,MATCH(K15,Readiness!$A$5:$A$9,0)),Readiness!$B$8)) -> 3 | M15: =IF(I15="","",IF(G15=0,"Regulated, stays human",IF(AND(I15>0,RANK(I15,$I$5:$I$24,0)<=Settings!$B$26),IF(L15>=Settings!$B$27,"Phase 1","Fix first"),IF(L15>=Settings!$B$27,"Later","Leave with humans")))) -> Later | N15: =IF(OR(C15="",D15=""),0,IF(LEFT(D15,13)="Informational",C15,0)) -> 0 | O15: =IF(OR(C15="",D15=""),0,IF(LEFT(D15,13)="Transactional",C15,0)) -> 0.03 | P15: =IF(M15="Phase 1",COUNTIF($M$5:M15,"Phase 1"),"") | Q15: =IF(M15="Fix first",COUNTIF($M$5:M15,"Fix first"),"")
A16: 12 | B16: Complaint | C16: 0.04 | D16: Complex | E16: High | G16: =IF(D16="","",IFERROR(INDEX(Settings!$B$4:$B$9,MATCH(D16,Settings!$A$4:$A$9,0)),"")) -> 0.2 | H16: =IF(E16="","",IFERROR(INDEX(Settings!$B$12:$B$14,MATCH(E16,Settings!$A$12:$A$14,0)),"")) -> 0.5 | I16: =IF(OR(C16="",G16="",H16=""),"",C16*G16*H16) -> 0.004 | J16: =IF(I16="","",Profile!$C$4*I16*Questionnaire!$C$27*12) -> 7560 | K16: =IF(D16="","",IF(LEFT(D16,13)="Informational","Knowledge",IF(LEFT(D16,13)="Transactional","Integration","People"))) -> People | L16: =IF(K16="","",MIN(INDEX(Readiness!$B$5:$B$9,MATCH(K16,Readiness!$A$5:$A$9,0)),Readiness!$B$8)) -> 3 | M16: =IF(I16="","",IF(G16=0,"Regulated, stays human",IF(AND(I16>0,RANK(I16,$I$5:$I$24,0)<=Settings!$B$26),IF(L16>=Settings!$B$27,"Phase 1","Fix first"),IF(L16>=Settings!$B$27,"Later","Leave with humans")))) -> Later | N16: =IF(OR(C16="",D16=""),0,IF(LEFT(D16,13)="Informational",C16,0)) -> 0 | O16: =IF(OR(C16="",D16=""),0,IF(LEFT(D16,13)="Transactional",C16,0)) -> 0 | P16: =IF(M16="Phase 1",COUNTIF($M$5:M16,"Phase 1"),"") | Q16: =IF(M16="Fix first",COUNTIF($M$5:M16,"Fix first"),"")
A17: 13 | B17: How to read my meter | C17: 0.02 | D17: Informational, content exists | E17: Low | G17: =IF(D17="","",IFERROR(INDEX(Settings!$B$4:$B$9,MATCH(D17,Settings!$A$4:$A$9,0)),"")) -> 1 | H17: =IF(E17="","",IFERROR(INDEX(Settings!$B$12:$B$14,MATCH(E17,Settings!$A$12:$A$14,0)),"")) -> 1 | I17: =IF(OR(C17="",G17="",H17=""),"",C17*G17*H17) -> 0.02 | J17: =IF(I17="","",Profile!$C$4*I17*Questionnaire!$C$27*12) -> 37800 | K17: =IF(D17="","",IF(LEFT(D17,13)="Informational","Knowledge",IF(LEFT(D17,13)="Transactional","Integration","People"))) -> Knowledge | L17: =IF(K17="","",MIN(INDEX(Readiness!$B$5:$B$9,MATCH(K17,Readiness!$A$5:$A$9,0)),Readiness!$B$8)) -> 2 | M17: =IF(I17="","",IF(G17=0,"Regulated, stays human",IF(AND(I17>0,RANK(I17,$I$5:$I$24,0)<=Settings!$B$26),IF(L17>=Settings!$B$27,"Phase 1","Fix first"),IF(L17>=Settings!$B$27,"Later","Leave with humans")))) -> Leave with humans | N17: =IF(OR(C17="",D17=""),0,IF(LEFT(D17,13)="Informational",C17,0)) -> 0.02 | O17: =IF(OR(C17="",D17=""),0,IF(LEFT(D17,13)="Transactional",C17,0)) -> 0 | P17: =IF(M17="Phase 1",COUNTIF($M$5:M17,"Phase 1"),"") | Q17: =IF(M17="Fix first",COUNTIF($M$5:M17,"Fix first"),"")
A18: 14 | B18: Account balance | C18: 0.05 | D18: Transactional, API exists | E18: Low | F18: Billing API | G18: =IF(D18="","",IFERROR(INDEX(Settings!$B$4:$B$9,MATCH(D18,Settings!$A$4:$A$9,0)),"")) -> 0.9 | H18: =IF(E18="","",IFERROR(INDEX(Settings!$B$12:$B$14,MATCH(E18,Settings!$A$12:$A$14,0)),"")) -> 1 | I18: =IF(OR(C18="",G18="",H18=""),"",C18*G18*H18) -> 0.045 | J18: =IF(I18="","",Profile!$C$4*I18*Questionnaire!$C$27*12) -> 85050 | K18: =IF(D18="","",IF(LEFT(D18,13)="Informational","Knowledge",IF(LEFT(D18,13)="Transactional","Integration","People"))) -> Integration | L18: =IF(K18="","",MIN(INDEX(Readiness!$B$5:$B$9,MATCH(K18,Readiness!$A$5:$A$9,0)),Readiness!$B$8)) -> 3 | M18: =IF(I18="","",IF(G18=0,"Regulated, stays human",IF(AND(I18>0,RANK(I18,$I$5:$I$24,0)<=Settings!$B$26),IF(L18>=Settings!$B$27,"Phase 1","Fix first"),IF(L18>=Settings!$B$27,"Later","Leave with humans")))) -> Phase 1 | N18: =IF(OR(C18="",D18=""),0,IF(LEFT(D18,13)="Informational",C18,0)) -> 0 | O18: =IF(OR(C18="",D18=""),0,IF(LEFT(D18,13)="Transactional",C18,0)) -> 0.05 | P18: =IF(M18="Phase 1",COUNTIF($M$5:M18,"Phase 1"),"") -> 4 | Q18: =IF(M18="Fix first",COUNTIF($M$5:M18,"Fix first"),"")
A19: 15 | B19: Switching provider or leaving | C19: 0.03 | D19: Complex | E19: Medium | G19: =IF(D19="","",IFERROR(INDEX(Settings!$B$4:$B$9,MATCH(D19,Settings!$A$4:$A$9,0)),"")) -> 0.2 | H19: =IF(E19="","",IFERROR(INDEX(Settings!$B$12:$B$14,MATCH(E19,Settings!$A$12:$A$14,0)),"")) -> 0.8 | I19: =IF(OR(C19="",G19="",H19=""),"",C19*G19*H19) -> 0.0048 | J19: =IF(I19="","",Profile!$C$4*I19*Questionnaire!$C$27*12) -> 9072 | K19: =IF(D19="","",IF(LEFT(D19,13)="Informational","Knowledge",IF(LEFT(D19,13)="Transactional","Integration","People"))) -> People | L19: =IF(K19="","",MIN(INDEX(Readiness!$B$5:$B$9,MATCH(K19,Readiness!$A$5:$A$9,0)),Readiness!$B$8)) -> 3 | M19: =IF(I19="","",IF(G19=0,"Regulated, stays human",IF(AND(I19>0,RANK(I19,$I$5:$I$24,0)<=Settings!$B$26),IF(L19>=Settings!$B$27,"Phase 1","Fix first"),IF(L19>=Settings!$B$27,"Later","Leave with humans")))) -> Later | N19: =IF(OR(C19="",D19=""),0,IF(LEFT(D19,13)="Informational",C19,0)) -> 0 | O19: =IF(OR(C19="",D19=""),0,IF(LEFT(D19,13)="Transactional",C19,0)) -> 0 | P19: =IF(M19="Phase 1",COUNTIF($M$5:M19,"Phase 1"),"") | Q19: =IF(M19="Fix first",COUNTIF($M$5:M19,"Fix first"),"")
A20: 16 | B20: Priority services register | C20: 0.02 | D20: Regulated | E20: High | F20: Vulnerability, human | G20: =IF(D20="","",IFERROR(INDEX(Settings!$B$4:$B$9,MATCH(D20,Settings!$A$4:$A$9,0)),"")) -> 0 | H20: =IF(E20="","",IFERROR(INDEX(Settings!$B$12:$B$14,MATCH(E20,Settings!$A$12:$A$14,0)),"")) -> 0.5 | I20: =IF(OR(C20="",G20="",H20=""),"",C20*G20*H20) -> 0 | J20: =IF(I20="","",Profile!$C$4*I20*Questionnaire!$C$27*12) -> 0 | K20: =IF(D20="","",IF(LEFT(D20,13)="Informational","Knowledge",IF(LEFT(D20,13)="Transactional","Integration","People"))) -> People | L20: =IF(K20="","",MIN(INDEX(Readiness!$B$5:$B$9,MATCH(K20,Readiness!$A$5:$A$9,0)),Readiness!$B$8)) -> 3 | M20: =IF(I20="","",IF(G20=0,"Regulated, stays human",IF(AND(I20>0,RANK(I20,$I$5:$I$24,0)<=Settings!$B$26),IF(L20>=Settings!$B$27,"Phase 1","Fix first"),IF(L20>=Settings!$B$27,"Later","Leave with humans")))) -> Regulated, stays human | N20: =IF(OR(C20="",D20=""),0,IF(LEFT(D20,13)="Informational",C20,0)) -> 0 | O20: =IF(OR(C20="",D20=""),0,IF(LEFT(D20,13)="Transactional",C20,0)) -> 0 | P20: =IF(M20="Phase 1",COUNTIF($M$5:M20,"Phase 1"),"") | Q20: =IF(M20="Fix first",COUNTIF($M$5:M20,"Fix first"),"")
A21: 17 | B21: App or login problems | C21: 0.03 | D21: Informational, content needs writing | E21: Low | G21: =IF(D21="","",IFERROR(INDEX(Settings!$B$4:$B$9,MATCH(D21,Settings!$A$4:$A$9,0)),"")) -> 0.8 | H21: =IF(E21="","",IFERROR(INDEX(Settings!$B$12:$B$14,MATCH(E21,Settings!$A$12:$A$14,0)),"")) -> 1 | I21: =IF(OR(C21="",G21="",H21=""),"",C21*G21*H21) -> 0.024 | J21: =IF(I21="","",Profile!$C$4*I21*Questionnaire!$C$27*12) -> 45360 | K21: =IF(D21="","",IF(LEFT(D21,13)="Informational","Knowledge",IF(LEFT(D21,13)="Transactional","Integration","People"))) -> Knowledge | L21: =IF(K21="","",MIN(INDEX(Readiness!$B$5:$B$9,MATCH(K21,Readiness!$A$5:$A$9,0)),Readiness!$B$8)) -> 2 | M21: =IF(I21="","",IF(G21=0,"Regulated, stays human",IF(AND(I21>0,RANK(I21,$I$5:$I$24,0)<=Settings!$B$26),IF(L21>=Settings!$B$27,"Phase 1","Fix first"),IF(L21>=Settings!$B$27,"Later","Leave with humans")))) -> Leave with humans | N21: =IF(OR(C21="",D21=""),0,IF(LEFT(D21,13)="Informational",C21,0)) -> 0.03 | O21: =IF(OR(C21="",D21=""),0,IF(LEFT(D21,13)="Transactional",C21,0)) -> 0 | P21: =IF(M21="Phase 1",COUNTIF($M$5:M21,"Phase 1"),"") | Q21: =IF(M21="Fix first",COUNTIF($M$5:M21,"Fix first"),"")
A22: 18 | B22: Energy saving advice | C22: 0.02 | D22: Informational, content needs writing | E22: Low | G22: =IF(D22="","",IFERROR(INDEX(Settings!$B$4:$B$9,MATCH(D22,Settings!$A$4:$A$9,0)),"")) -> 0.8 | H22: =IF(E22="","",IFERROR(INDEX(Settings!$B$12:$B$14,MATCH(E22,Settings!$A$12:$A$14,0)),"")) -> 1 | I22: =IF(OR(C22="",G22="",H22=""),"",C22*G22*H22) -> 0.016 | J22: =IF(I22="","",Profile!$C$4*I22*Questionnaire!$C$27*12) -> 30240 | K22: =IF(D22="","",IF(LEFT(D22,13)="Informational","Knowledge",IF(LEFT(D22,13)="Transactional","Integration","People"))) -> Knowledge | L22: =IF(K22="","",MIN(INDEX(Readiness!$B$5:$B$9,MATCH(K22,Readiness!$A$5:$A$9,0)),Readiness!$B$8)) -> 2 | M22: =IF(I22="","",IF(G22=0,"Regulated, stays human",IF(AND(I22>0,RANK(I22,$I$5:$I$24,0)<=Settings!$B$26),IF(L22>=Settings!$B$27,"Phase 1","Fix first"),IF(L22>=Settings!$B$27,"Later","Leave with humans")))) -> Leave with humans | N22: =IF(OR(C22="",D22=""),0,IF(LEFT(D22,13)="Informational",C22,0)) -> 0.02 | O22: =IF(OR(C22="",D22=""),0,IF(LEFT(D22,13)="Transactional",C22,0)) -> 0 | P22: =IF(M22="Phase 1",COUNTIF($M$5:M22,"Phase 1"),"") | Q22: =IF(M22="Fix first",COUNTIF($M$5:M22,"Fix first"),"")
A23: 19 | B23: Warm home discount eligibility | C23: 0.03 | D23: Informational, content exists | E23: Medium | G23: =IF(D23="","",IFERROR(INDEX(Settings!$B$4:$B$9,MATCH(D23,Settings!$A$4:$A$9,0)),"")) -> 1 | H23: =IF(E23="","",IFERROR(INDEX(Settings!$B$12:$B$14,MATCH(E23,Settings!$A$12:$A$14,0)),"")) -> 0.8 | I23: =IF(OR(C23="",G23="",H23=""),"",C23*G23*H23) -> 0.024 | J23: =IF(I23="","",Profile!$C$4*I23*Questionnaire!$C$27*12) -> 45360 | K23: =IF(D23="","",IF(LEFT(D23,13)="Informational","Knowledge",IF(LEFT(D23,13)="Transactional","Integration","People"))) -> Knowledge | L23: =IF(K23="","",MIN(INDEX(Readiness!$B$5:$B$9,MATCH(K23,Readiness!$A$5:$A$9,0)),Readiness!$B$8)) -> 2 | M23: =IF(I23="","",IF(G23=0,"Regulated, stays human",IF(AND(I23>0,RANK(I23,$I$5:$I$24,0)<=Settings!$B$26),IF(L23>=Settings!$B$27,"Phase 1","Fix first"),IF(L23>=Settings!$B$27,"Later","Leave with humans")))) -> Leave with humans | N23: =IF(OR(C23="",D23=""),0,IF(LEFT(D23,13)="Informational",C23,0)) -> 0.03 | O23: =IF(OR(C23="",D23=""),0,IF(LEFT(D23,13)="Transactional",C23,0)) -> 0 | P23: =IF(M23="Phase 1",COUNTIF($M$5:M23,"Phase 1"),"") | Q23: =IF(M23="Fix first",COUNTIF($M$5:M23,"Fix first"),"")
A24: 20 | B24: Change tariff | C24: 0.03 | D24: Transactional, API exists | E24: Medium | F24: Billing API | G24: =IF(D24="","",IFERROR(INDEX(Settings!$B$4:$B$9,MATCH(D24,Settings!$A$4:$A$9,0)),"")) -> 0.9 | H24: =IF(E24="","",IFERROR(INDEX(Settings!$B$12:$B$14,MATCH(E24,Settings!$A$12:$A$14,0)),"")) -> 0.8 | I24: =IF(OR(C24="",G24="",H24=""),"",C24*G24*H24) -> 0.0216 | J24: =IF(I24="","",Profile!$C$4*I24*Questionnaire!$C$27*12) -> 40824 | K24: =IF(D24="","",IF(LEFT(D24,13)="Informational","Knowledge",IF(LEFT(D24,13)="Transactional","Integration","People"))) -> Integration | L24: =IF(K24="","",MIN(INDEX(Readiness!$B$5:$B$9,MATCH(K24,Readiness!$A$5:$A$9,0)),Readiness!$B$8)) -> 3 | M24: =IF(I24="","",IF(G24=0,"Regulated, stays human",IF(AND(I24>0,RANK(I24,$I$5:$I$24,0)<=Settings!$B$26),IF(L24>=Settings!$B$27,"Phase 1","Fix first"),IF(L24>=Settings!$B$27,"Later","Leave with humans")))) -> Later | N24: =IF(OR(C24="",D24=""),0,IF(LEFT(D24,13)="Informational",C24,0)) -> 0 | O24: =IF(OR(C24="",D24=""),0,IF(LEFT(D24,13)="Transactional",C24,0)) -> 0.03 | P24: =IF(M24="Phase 1",COUNTIF($M$5:M24,"Phase 1"),"") | Q24: =IF(M24="Fix first",COUNTIF($M$5:M24,"Fix first"),"")
B25: Totals | C25: =SUM(C5:C24) -> 0.93 | I25: =SUM(I5:I24) -> 0.5162 | J25: =SUM(J5:J24) -> 975618 | N25: =SUM(N5:N24) -> 0.14 | O25: =SUM(O5:O24) -> 0.51

Sheet Profile
A1: Requirements profile and column weights
A2: All computed. Change the rules on Settings, not here.
A3: Field | B3: Source | C3: Value
A4: Total monthly contacts | B4: A1 | C4: =SUM(Questionnaire!$C$8,Questionnaire!$C$9,Questionnaire!$C$10,Questionnaire!$C$11,Questionnaire!$C$12,Questionnaire!$C$13) -> 35000
A5: Voice share of volume | B5: A1 | C5: =IF(C4=0,0,Questionnaire!$C$8/C4) -> 0.51428571
A6: Messaging share (chat, social, in-app) | B6: A1 | C6: =IF(C4=0,0,(Questionnaire!$C$9+Questionnaire!$C$11+Questionnaire!$C$12)/C4) -> 0.22857143
A7: Informational share of volume | B7: B2 | C7: =Intents!$N$25 -> 0.14
A8: Transactional share of volume | B8: B2 | C8: =Intents!$O$25 -> 0.51
A9: Automatable share of contacts | B9: Intents | C9: =Intents!$I$25 -> 0.5162
A10: Languages | B10: A4 | C10: =Questionnaire!$C$16 -> 2
A11: Auth needed | B11: A6 | C11: =Questionnaire!$C$19 -> Yes
A12: Builder skills in-house | B12: E2 | C12: =Questionnaire!$C$47 -> Some
A13: Bot owner | B13: E1 | C13: =Questionnaire!$C$46 -> CX team
A14: People score | B14: Readiness | C14: =Readiness!$B$8 -> 3
A15: Data score | B15: Readiness | C15: =Readiness!$B$5 -> 3
A16: Regulated or residency flag | B16: F1, C5 | C16: =IF(OR(Questionnaire!$C$54="Yes",Questionnaire!$C$55="Yes",Questionnaire!$C$56="Yes",Questionnaire!$C$57="Yes",Questionnaire!$C$58="Yes",Questionnaire!$C$34="UK only"),"Yes","No") -> Yes
A17: Budget band index | B17: G3 | C17: =IFERROR(INDEX(Settings!$B$30:$B$33,MATCH(Questionnaire!$C$67,Settings!$A$30:$A$33,0)),0) -> 3
A20: Capability column | B20: Weight (0 to 3) | C20: Rule
A21: Voice | B21: =IF(C5>=Settings!$B$21,3,IF(C5>=Settings!$B$22,1,0)) -> 3 | C21: 3 if voice share over 40%, 1 if 10 to 40%, else 0
A22: Chat and messaging | B22: =IF(C6>=0.1,3,IF(C6>0,1,0)) -> 3 | C22: 3 if messaging share is 10% or more, 1 if any, else 0
A23: Languages | B23: =IF(C10>Settings!$B$25,2,0) -> 0 | C23: 2 if more than two languages
A24: Knowledge and RAG | B24: =IF(C7>=Settings!$B$24,3,IF(C7>=0.2,2,1)) -> 1 | C24: 3 if informational share over 40%, 2 if over 20%, else 1
A25: Integration tooling | B25: =IF(C8>=Settings!$B$23,3,IF(C8>=0.1,2,1)) -> 3 | C25: 3 if transactional share over 25%, 2 if over 10%, else 1
A26: Agentic actions | B26: =IF(C8>=Settings!$B$23,2,0) -> 2 | C26: 2 if transactional share over 25%
A27: Auth handling | B27: =IF(C11="Yes",3,0) -> 3 | C27: 3 if customers must be identified
A28: Agent handoff | B28: =3 -> 3 | C28: Always 3: there is always a handoff target
A29: Build model | B29: =IF(C12="None",3,IF(C12="Some",1,0)) -> 1 | C29: 3 if nobody builds in-house, 1 if some skills, 0 if yes
A30: Analytics and intent discovery | B30: =IF(C15<=2,3,2) -> 2 | C30: 3 if Data readiness is 2 or under, else 2
A31: Pricing model | B31: =2 -> 2 | C31: Always 2
A32: Minimum team to run | B32: =IF(C14<=2,3,1) -> 1 | C32: 3 if People readiness is 2 or under, else 1
A33: Compliance and residency | B33: =IF(C16="Yes",3,0) -> 3 | C33: 3 if any regulated flag or UK-only hosting

Sheet Matrix
A1: Fit matrix
A2: Score each platform 0 to 3 per column (0 none, 1 basic, 2 solid, 3 best in class). Real platform rows are blank for the team to fill. Example rows are illustrative placeholders, not real platforms.
B3: Weight (from Profile) | C3: =Profile!$B$21 -> 3 | D3: =Profile!$B$22 -> 3 | E3: =Profile!$B$23 -> 0 | F3: =Profile!$B$24 -> 1 | G3: =Profile!$B$25 -> 3 | H3: =Profile!$B$26 -> 2 | I3: =Profile!$B$27 -> 3 | J3: =Profile!$B$28 -> 3 | K3: =Profile!$B$29 -> 1 | L3: =Profile!$B$30 -> 2 | M3: =Profile!$B$31 -> 2 | N3: =Profile!$B$32 -> 1 | O3: =Profile!$B$33 -> 3
A4: Platform | B4: Year-one cost band | C4: Voice | D4: Chat and messaging | E4: Languages | F4: Knowledge and RAG | G4: Integration tooling | H4: Agentic actions | I4: Auth handling | J4: Agent handoff | K4: Build model | L4: Analytics and intent discovery | M4: Pricing model | N4: Minimum team to run | O4: Compliance and residency | P4: Columns scored | Q4: Fit score | R4: Over-spec index | S4: Within budget? | T4: Rank | U4: Rankable fit
A5: Help centre plus ticketing vendor's native bot | P5: =COUNT(C5:O5) -> 0 | Q5: =IF(P5<13,"",IF(SUM($C$3:$O$3)=0,0,SUMPRODUCT($C$3:$O$3,C5:O5)/(3*SUM($C$3:$O$3)))) | R5: =IF(P5<13,"",SUMPRODUCT(($C$3:$O$3=0)*C5:O5)) | S5: =IF(B5="","",IF(Profile!$C$17=0,"No budget set",IF(IFERROR(INDEX(Settings!$B$30:$B$33,MATCH(B5,Settings!$A$30:$A$33,0)),9)<=Profile!$C$17,"Yes","Over budget"))) | T5: =IF(U5="","",RANK(U5,$U$5:$U$14,0)) | U5: =IF(AND(Q5<>"",S5="Yes"),Q5,"")
A6: Ultimate AI / Zendesk AI agents | P6: =COUNT(C6:O6) -> 0 | Q6: =IF(P6<13,"",IF(SUM($C$3:$O$3)=0,0,SUMPRODUCT($C$3:$O$3,C6:O6)/(3*SUM($C$3:$O$3)))) | R6: =IF(P6<13,"",SUMPRODUCT(($C$3:$O$3=0)*C6:O6)) | S6: =IF(B6="","",IF(Profile!$C$17=0,"No budget set",IF(IFERROR(INDEX(Settings!$B$30:$B$33,MATCH(B6,Settings!$A$30:$A$33,0)),9)<=Profile!$C$17,"Yes","Over budget"))) | T6: =IF(U6="","",RANK(U6,$U$5:$U$14,0)) | U6: =IF(AND(Q6<>"",S6="Yes"),Q6,"")
A7: Cognigy (NiCE) | P7: =COUNT(C7:O7) -> 0 | Q7: =IF(P7<13,"",IF(SUM($C$3:$O$3)=0,0,SUMPRODUCT($C$3:$O$3,C7:O7)/(3*SUM($C$3:$O$3)))) | R7: =IF(P7<13,"",SUMPRODUCT(($C$3:$O$3=0)*C7:O7)) | S7: =IF(B7="","",IF(Profile!$C$17=0,"No budget set",IF(IFERROR(INDEX(Settings!$B$30:$B$33,MATCH(B7,Settings!$A$30:$A$33,0)),9)<=Profile!$C$17,"Yes","Over budget"))) | T7: =IF(U7="","",RANK(U7,$U$5:$U$14,0)) | U7: =IF(AND(Q7<>"",S7="Yes"),Q7,"")
A8: Omilia | P8: =COUNT(C8:O8) -> 0 | Q8: =IF(P8<13,"",IF(SUM($C$3:$O$3)=0,0,SUMPRODUCT($C$3:$O$3,C8:O8)/(3*SUM($C$3:$O$3)))) | R8: =IF(P8<13,"",SUMPRODUCT(($C$3:$O$3=0)*C8:O8)) | S8: =IF(B8="","",IF(Profile!$C$17=0,"No budget set",IF(IFERROR(INDEX(Settings!$B$30:$B$33,MATCH(B8,Settings!$A$30:$A$33,0)),9)<=Profile!$C$17,"Yes","Over budget"))) | T8: =IF(U8="","",RANK(U8,$U$5:$U$14,0)) | U8: =IF(AND(Q8<>"",S8="Yes"),Q8,"")
A9: PolyAI | P9: =COUNT(C9:O9) -> 0 | Q9: =IF(P9<13,"",IF(SUM($C$3:$O$3)=0,0,SUMPRODUCT($C$3:$O$3,C9:O9)/(3*SUM($C$3:$O$3)))) | R9: =IF(P9<13,"",SUMPRODUCT(($C$3:$O$3=0)*C9:O9)) | S9: =IF(B9="","",IF(Profile!$C$17=0,"No budget set",IF(IFERROR(INDEX(Settings!$B$30:$B$33,MATCH(B9,Settings!$A$30:$A$33,0)),9)<=Profile!$C$17,"Yes","Over budget"))) | T9: =IF(U9="","",RANK(U9,$U$5:$U$14,0)) | U9: =IF(AND(Q9<>"",S9="Yes"),Q9,"")
A10: NICE CXone native bots | P10: =COUNT(C10:O10) -> 0 | Q10: =IF(P10<13,"",IF(SUM($C$3:$O$3)=0,0,SUMPRODUCT($C$3:$O$3,C10:O10)/(3*SUM($C$3:$O$3)))) | R10: =IF(P10<13,"",SUMPRODUCT(($C$3:$O$3=0)*C10:O10)) | S10: =IF(B10="","",IF(Profile!$C$17=0,"No budget set",IF(IFERROR(INDEX(Settings!$B$30:$B$33,MATCH(B10,Settings!$A$30:$A$33,0)),9)<=Profile!$C$17,"Yes","Over budget"))) | T10: =IF(U10="","",RANK(U10,$U$5:$U$14,0)) | U10: =IF(AND(Q10<>"",S10="Yes"),Q10,"")
A11: Microsoft Copilot Studio / Azure | P11: =COUNT(C11:O11) -> 0 | Q11: =IF(P11<13,"",IF(SUM($C$3:$O$3)=0,0,SUMPRODUCT($C$3:$O$3,C11:O11)/(3*SUM($C$3:$O$3)))) | R11: =IF(P11<13,"",SUMPRODUCT(($C$3:$O$3=0)*C11:O11)) | S11: =IF(B11="","",IF(Profile!$C$17=0,"No budget set",IF(IFERROR(INDEX(Settings!$B$30:$B$33,MATCH(B11,Settings!$A$30:$A$33,0)),9)<=Profile!$C$17,"Yes","Over budget"))) | T11: =IF(U11="","",RANK(U11,$U$5:$U$14,0)) | U11: =IF(AND(Q11<>"",S11="Yes"),Q11,"")
A12: Example platform A (illustrative) | B12: £50k to £150k | C12: 3 | D12: 2 | E12: 1 | F12: 2 | G12: 2 | H12: 1 | I12: 2 | J12: 3 | K12: 2 | L12: 2 | M12: 2 | N12: 2 | O12: 3 | P12: =COUNT(C12:O12) -> 13 | Q12: =IF(P12<13,"",IF(SUM($C$3:$O$3)=0,0,SUMPRODUCT($C$3:$O$3,C12:O12)/(3*SUM($C$3:$O$3)))) -> 0.75308642 | R12: =IF(P12<13,"",SUMPRODUCT(($C$3:$O$3=0)*C12:O12)) -> 1 | S12: =IF(B12="","",IF(Profile!$C$17=0,"No budget set",IF(IFERROR(INDEX(Settings!$B$30:$B$33,MATCH(B12,Settings!$A$30:$A$33,0)),9)<=Profile!$C$17,"Yes","Over budget"))) -> Yes | T12: =IF(U12="","",RANK(U12,$U$5:$U$14,0)) -> 2 | U12: =IF(AND(Q12<>"",S12="Yes"),Q12,"") -> 0.75308642
A13: Example platform B (illustrative) | B13: £150k to £400k | C13: 3 | D13: 3 | E13: 3 | F13: 3 | G13: 3 | H13: 3 | I13: 3 | J13: 3 | K13: 1 | L13: 3 | M13: 1 | N13: 1 | O13: 3 | P13: =COUNT(C13:O13) -> 13 | Q13: =IF(P13<13,"",IF(SUM($C$3:$O$3)=0,0,SUMPRODUCT($C$3:$O$3,C13:O13)/(3*SUM($C$3:$O$3)))) -> 0.90123457 | R13: =IF(P13<13,"",SUMPRODUCT(($C$3:$O$3=0)*C13:O13)) -> 3 | S13: =IF(B13="","",IF(Profile!$C$17=0,"No budget set",IF(IFERROR(INDEX(Settings!$B$30:$B$33,MATCH(B13,Settings!$A$30:$A$33,0)),9)<=Profile!$C$17,"Yes","Over budget"))) -> Yes | T13: =IF(U13="","",RANK(U13,$U$5:$U$14,0)) -> 1 | U13: =IF(AND(Q13<>"",S13="Yes"),Q13,"") -> 0.90123457
A14: Example platform C (illustrative) | B14: Under £50k | C14: 0 | D14: 3 | E14: 1 | F14: 3 | G14: 1 | H14: 0 | I14: 1 | J14: 2 | K14: 3 | L14: 2 | M14: 3 | N14: 3 | O14: 2 | P14: =COUNT(C14:O14) -> 13 | Q14: =IF(P14<13,"",IF(SUM($C$3:$O$3)=0,0,SUMPRODUCT($C$3:$O$3,C14:O14)/(3*SUM($C$3:$O$3)))) -> 0.56790123 | R14: =IF(P14<13,"",SUMPRODUCT(($C$3:$O$3=0)*C14:O14)) -> 1 | S14: =IF(B14="","",IF(Profile!$C$17=0,"No budget set",IF(IFERROR(INDEX(Settings!$B$30:$B$33,MATCH(B14,Settings!$A$30:$A$33,0)),9)<=Profile!$C$17,"Yes","Over budget"))) -> Yes | T14: =IF(U14="","",RANK(U14,$U$5:$U$14,0)) -> 3 | U14: =IF(AND(Q14<>"",S14="Yes"),Q14,"") -> 0.56790123

Sheet Results
A1: Results
A2: Client | B2: =Questionnaire!$C$3 -> Example Energy Co (illustrative)
A3: Date | B3: =Questionnaire!$C$4 -> 2026-10-05
A5: Headline | B5: Value
A6: Automatable share of contacts | B6: =Intents!$I$25 -> 0.5162
A7: Informational share of volume | B7: =Profile!$C$7 -> 0.14
A8: Transactional share of volume | B8: =Profile!$C$8 -> 0.51
A9: Voice share of volume | B9: =Profile!$C$5 -> 0.51428571
A10: Annual value of automatable contacts (£, illustrative) | B10: =Intents!$J$25 -> 975618
A11: Average readiness (1 to 5) | B11: =Readiness!$B$12 -> 3
A12: People gate | B12: =Readiness!$B$11 -> Open
A13: Recommended path | B13: =IF(Readiness!$B$8<=1,"No platform yet. Name an owner first.",IF(B6<Settings!$B$17,"No platform. Fix the help centre and the top three processes.",IF(B6<Settings!$B$18,IF(B8>=Settings!$B$20,"Platform with integration tooling. Phase 1 is two intents that already have APIs.","Knowledge-led bot on a lighter platform, or the ticketing vendor's own AI."),IF(B9>=Settings!$B$19,"Full platform, voice-capable first, chat second.","Full platform. Voice only if the voice share earns it.")))) -> Full platform, voice-capable first, chat second.
A15: Phase 1 candidates | B15: Share of volume | C15: Annual value (£, illustrative) | D15: Depends on
A16: =IFERROR(INDEX(Intents!$B$5:$B$24,MATCH(1,Intents!$P$5:$P$24,0)),"") -> Submit a meter reading | B16: =IFERROR(INDEX(Intents!$C$5:$C$24,MATCH(1,Intents!$P$5:$P$24,0)),"") -> 0.11 | C16: =IFERROR(INDEX(Intents!$J$5:$J$24,MATCH(1,Intents!$P$5:$P$24,0)),"") -> 187110 | D16: =IFERROR(INDEX(Intents!$K$5:$K$24,MATCH(1,Intents!$P$5:$P$24,0)),"") -> Integration
A17: =IFERROR(INDEX(Intents!$B$5:$B$24,MATCH(2,Intents!$P$5:$P$24,0)),"") -> Make a payment | B17: =IFERROR(INDEX(Intents!$C$5:$C$24,MATCH(2,Intents!$P$5:$P$24,0)),"") -> 0.09 | C17: =IFERROR(INDEX(Intents!$J$5:$J$24,MATCH(2,Intents!$P$5:$P$24,0)),"") -> 122472 | D17: =IFERROR(INDEX(Intents!$K$5:$K$24,MATCH(2,Intents!$P$5:$P$24,0)),"") -> Integration
A18: =IFERROR(INDEX(Intents!$B$5:$B$24,MATCH(3,Intents!$P$5:$P$24,0)),"") -> Update contact details | B18: =IFERROR(INDEX(Intents!$C$5:$C$24,MATCH(3,Intents!$P$5:$P$24,0)),"") -> 0.05 | C18: =IFERROR(INDEX(Intents!$J$5:$J$24,MATCH(3,Intents!$P$5:$P$24,0)),"") -> 85050 | D18: =IFERROR(INDEX(Intents!$K$5:$K$24,MATCH(3,Intents!$P$5:$P$24,0)),"") -> Integration
A19: =IFERROR(INDEX(Intents!$B$5:$B$24,MATCH(4,Intents!$P$5:$P$24,0)),"") -> Account balance | B19: =IFERROR(INDEX(Intents!$C$5:$C$24,MATCH(4,Intents!$P$5:$P$24,0)),"") -> 0.05 | C19: =IFERROR(INDEX(Intents!$J$5:$J$24,MATCH(4,Intents!$P$5:$P$24,0)),"") -> 85050 | D19: =IFERROR(INDEX(Intents!$K$5:$K$24,MATCH(4,Intents!$P$5:$P$24,0)),"") -> Integration
A20: =IFERROR(INDEX(Intents!$B$5:$B$24,MATCH(5,Intents!$P$5:$P$24,0)),"") | B20: =IFERROR(INDEX(Intents!$C$5:$C$24,MATCH(5,Intents!$P$5:$P$24,0)),"") | C20: =IFERROR(INDEX(Intents!$J$5:$J$24,MATCH(5,Intents!$P$5:$P$24,0)),"") | D20: =IFERROR(INDEX(Intents!$K$5:$K$24,MATCH(5,Intents!$P$5:$P$24,0)),"")
A22: Fix first (high opportunity, a dimension under 3) | B22: Share of volume | C22: Depends on | D22: Dimension score
A23: =IFERROR(INDEX(Intents!$B$5:$B$24,MATCH(1,Intents!$Q$5:$Q$24,0)),"") -> Tariff information | B23: =IFERROR(INDEX(Intents!$C$5:$C$24,MATCH(1,Intents!$Q$5:$Q$24,0)),"") -> 0.04 | C23: =IFERROR(INDEX(Intents!$K$5:$K$24,MATCH(1,Intents!$Q$5:$Q$24,0)),"") -> Knowledge | D23: =IFERROR(INDEX(Intents!$L$5:$L$24,MATCH(1,Intents!$Q$5:$Q$24,0)),"") -> 2
A24: =IFERROR(INDEX(Intents!$B$5:$B$24,MATCH(2,Intents!$Q$5:$Q$24,0)),"") | B24: =IFERROR(INDEX(Intents!$C$5:$C$24,MATCH(2,Intents!$Q$5:$Q$24,0)),"") | C24: =IFERROR(INDEX(Intents!$K$5:$K$24,MATCH(2,Intents!$Q$5:$Q$24,0)),"") | D24: =IFERROR(INDEX(Intents!$L$5:$L$24,MATCH(2,Intents!$Q$5:$Q$24,0)),"")
A25: =IFERROR(INDEX(Intents!$B$5:$B$24,MATCH(3,Intents!$Q$5:$Q$24,0)),"") | B25: =IFERROR(INDEX(Intents!$C$5:$C$24,MATCH(3,Intents!$Q$5:$Q$24,0)),"") | C25: =IFERROR(INDEX(Intents!$K$5:$K$24,MATCH(3,Intents!$Q$5:$Q$24,0)),"") | D25: =IFERROR(INDEX(Intents!$L$5:$L$24,MATCH(3,Intents!$Q$5:$Q$24,0)),"")
A26: =IFERROR(INDEX(Intents!$B$5:$B$24,MATCH(4,Intents!$Q$5:$Q$24,0)),"") | B26: =IFERROR(INDEX(Intents!$C$5:$C$24,MATCH(4,Intents!$Q$5:$Q$24,0)),"") | C26: =IFERROR(INDEX(Intents!$K$5:$K$24,MATCH(4,Intents!$Q$5:$Q$24,0)),"") | D26: =IFERROR(INDEX(Intents!$L$5:$L$24,MATCH(4,Intents!$Q$5:$Q$24,0)),"")
A27: =IFERROR(INDEX(Intents!$B$5:$B$24,MATCH(5,Intents!$Q$5:$Q$24,0)),"") | B27: =IFERROR(INDEX(Intents!$C$5:$C$24,MATCH(5,Intents!$Q$5:$Q$24,0)),"") | C27: =IFERROR(INDEX(Intents!$K$5:$K$24,MATCH(5,Intents!$Q$5:$Q$24,0)),"") | D27: =IFERROR(INDEX(Intents!$L$5:$L$24,MATCH(5,Intents!$Q$5:$Q$24,0)),"")
A29: Readiness fixes (score under 3) | B29: Score | C29: What a 3 looks like
A30: =IF(Readiness!$B$5<3,Readiness!$A$5,"") | B30: =IF(Readiness!$B$5<3,Readiness!$B$5,"") | C30: =IF(Readiness!$B$5<3,Readiness!$D$5,"")
A31: =IF(Readiness!$B$6<3,Readiness!$A$6,"") -> Knowledge | B31: =IF(Readiness!$B$6<3,Readiness!$B$6,"") -> 2 | C31: =IF(Readiness!$B$6<3,Readiness!$D$6,"") -> Exists, partly maintained
A32: =IF(Readiness!$B$7<3,Readiness!$A$7,"") | B32: =IF(Readiness!$B$7<3,Readiness!$B$7,"") | C32: =IF(Readiness!$B$7<3,Readiness!$D$7,"")
A33: =IF(Readiness!$B$8<3,Readiness!$A$8,"") | B33: =IF(Readiness!$B$8<3,Readiness!$B$8,"") | C33: =IF(Readiness!$B$8<3,Readiness!$D$8,"")
A34: =IF(Readiness!$B$9<3,Readiness!$A$9,"") | B34: =IF(Readiness!$B$9<3,Readiness!$B$9,"") | C34: =IF(Readiness!$B$9<3,Readiness!$D$9,"")
A36: Fit ranking (within budget, fully scored) | B36: Fit score | C36: Over-spec index | D36: Cost band
A37: =IFERROR(INDEX(Matrix!$A$5:$A$14,MATCH(1,Matrix!$T$5:$T$14,0)),"") -> Example platform B (illustrative) | B37: =IFERROR(INDEX(Matrix!$Q$5:$Q$14,MATCH(1,Matrix!$T$5:$T$14,0)),"") -> 0.90123457 | C37: =IFERROR(INDEX(Matrix!$R$5:$R$14,MATCH(1,Matrix!$T$5:$T$14,0)),"") -> 3 | D37: =IFERROR(INDEX(Matrix!$B$5:$B$14,MATCH(1,Matrix!$T$5:$T$14,0)),"") -> £150k to £400k
A38: =IFERROR(INDEX(Matrix!$A$5:$A$14,MATCH(2,Matrix!$T$5:$T$14,0)),"") -> Example platform A (illustrative) | B38: =IFERROR(INDEX(Matrix!$Q$5:$Q$14,MATCH(2,Matrix!$T$5:$T$14,0)),"") -> 0.75308642 | C38: =IFERROR(INDEX(Matrix!$R$5:$R$14,MATCH(2,Matrix!$T$5:$T$14,0)),"") -> 1 | D38: =IFERROR(INDEX(Matrix!$B$5:$B$14,MATCH(2,Matrix!$T$5:$T$14,0)),"") -> £50k to £150k
A39: =IFERROR(INDEX(Matrix!$A$5:$A$14,MATCH(3,Matrix!$T$5:$T$14,0)),"") -> Example platform C (illustrative) | B39: =IFERROR(INDEX(Matrix!$Q$5:$Q$14,MATCH(3,Matrix!$T$5:$T$14,0)),"") -> 0.56790123 | C39: =IFERROR(INDEX(Matrix!$R$5:$R$14,MATCH(3,Matrix!$T$5:$T$14,0)),"") -> 1 | D39: =IFERROR(INDEX(Matrix!$B$5:$B$14,MATCH(3,Matrix!$T$5:$T$14,0)),"") -> Under £50k
A40: =IFERROR(INDEX(Matrix!$A$5:$A$14,MATCH(4,Matrix!$T$5:$T$14,0)),"") | B40: =IFERROR(INDEX(Matrix!$Q$5:$Q$14,MATCH(4,Matrix!$T$5:$T$14,0)),"") | C40: =IFERROR(INDEX(Matrix!$R$5:$R$14,MATCH(4,Matrix!$T$5:$T$14,0)),"") | D40: =IFERROR(INDEX(Matrix!$B$5:$B$14,MATCH(4,Matrix!$T$5:$T$14,0)),"")
A41: =IFERROR(INDEX(Matrix!$A$5:$A$14,MATCH(5,Matrix!$T$5:$T$14,0)),"") | B41: =IFERROR(INDEX(Matrix!$Q$5:$Q$14,MATCH(5,Matrix!$T$5:$T$14,0)),"") | C41: =IFERROR(INDEX(Matrix!$R$5:$R$14,MATCH(5,Matrix!$T$5:$T$14,0)),"") | D41: =IFERROR(INDEX(Matrix!$B$5:$B$14,MATCH(5,Matrix!$T$5:$T$14,0)),"")
A42: =IFERROR(INDEX(Matrix!$A$5:$A$14,MATCH(6,Matrix!$T$5:$T$14,0)),"") | B42: =IFERROR(INDEX(Matrix!$Q$5:$Q$14,MATCH(6,Matrix!$T$5:$T$14,0)),"") | C42: =IFERROR(INDEX(Matrix!$R$5:$R$14,MATCH(6,Matrix!$T$5:$T$14,0)),"") | D42: =IFERROR(INDEX(Matrix!$B$5:$B$14,MATCH(6,Matrix!$T$5:$T$14,0)),"")
A43: =IFERROR(INDEX(Matrix!$A$5:$A$14,MATCH(7,Matrix!$T$5:$T$14,0)),"") | B43: =IFERROR(INDEX(Matrix!$Q$5:$Q$14,MATCH(7,Matrix!$T$5:$T$14,0)),"") | C43: =IFERROR(INDEX(Matrix!$R$5:$R$14,MATCH(7,Matrix!$T$5:$T$14,0)),"") | D43: =IFERROR(INDEX(Matrix!$B$5:$B$14,MATCH(7,Matrix!$T$5:$T$14,0)),"")
A44: =IFERROR(INDEX(Matrix!$A$5:$A$14,MATCH(8,Matrix!$T$5:$T$14,0)),"") | B44: =IFERROR(INDEX(Matrix!$Q$5:$Q$14,MATCH(8,Matrix!$T$5:$T$14,0)),"") | C44: =IFERROR(INDEX(Matrix!$R$5:$R$14,MATCH(8,Matrix!$T$5:$T$14,0)),"") | D44: =IFERROR(INDEX(Matrix!$B$5:$B$14,MATCH(8,Matrix!$T$5:$T$14,0)),"")
A45: =IFERROR(INDEX(Matrix!$A$5:$A$14,MATCH(9,Matrix!$T$5:$T$14,0)),"") | B45: =IFERROR(INDEX(Matrix!$Q$5:$Q$14,MATCH(9,Matrix!$T$5:$T$14,0)),"") | C45: =IFERROR(INDEX(Matrix!$R$5:$R$14,MATCH(9,Matrix!$T$5:$T$14,0)),"") | D45: =IFERROR(INDEX(Matrix!$B$5:$B$14,MATCH(9,Matrix!$T$5:$T$14,0)),"")
...
